<?xml version="1.0" ?>
<sdf version='1.5'>
  <model name='forklift_robot'>
    <link name='base_footprint'>
      <inertial>
        <pose>4.9e-05 0 3e-05 0 -0 0</pose>
        <mass>500.114</mass>
        <inertia>
          <ixx>206.003</ixx>
          <ixy>0</ixy>
          <ixz>-23.0032</ixz>
          <iyy>389.008</iyy>
          <iyz>0</iyz>
          <izz>316.006</izz>
        </inertia>
      </inertial>
      <collision name='base_footprint_fixed_joint_lump__base_link_collision'>
        <pose>0 0 0 0 -0 0</pose>
        <geometry>
          <mesh>
            <scale>1 1 1</scale>
            <uri>model://forklift_robot_description/meshes/base_link.dae</uri>
          </mesh>
        </geometry>
      </collision>
      <collision name='base_footprint_fixed_joint_lump__lidar_link_collision_1'>
        <pose>0.215 0 0.13 0 -0 0</pose>
        <geometry>
          <cylinder>
            <length>0.18</length>
            <radius>0.0508</radius>
          </cylinder>
        </geometry>
      </collision>
      <visual name='base_footprint_fixed_joint_lump__base_link_visual'>
        <pose>-1.0795 -0.5334 0 0 -0 0</pose>
        <geometry>
          <mesh>
            <scale>1 1 1</scale>
            <uri>model://forklift_robot_description/meshes/base_link.dae</uri>
          </mesh>
        </geometry>
      </visual>
      <visual name='base_footprint_fixed_joint_lump__lidar_link_visual_1'>
        <pose>0.215 0 0.13 0 -0 0</pose>
        <geometry>
          <cylinder>
            <length>0.18</length>
            <radius>0.0508</radius>
          </cylinder>
        </geometry>
      </visual>
    </link>
    <joint name='base_to_fork' type='prismatic'>
      <pose relative_to='base_footprint'>1.0795 -0.3686 0 0 -0 0</pose>
      <parent>base_footprint</parent>
      <child>fork</child>
      <axis>
        <xyz>0 0 1</xyz>
        <limit>
          <lower>0</lower>
          <upper>2</upper>
          <effort>100</effort>
          <velocity>0.1</velocity>
        </limit>
        <dynamics>
          <spring_reference>0</spring_reference>
          <spring_stiffness>0</spring_stiffness>
        </dynamics>
      </axis>
    </joint>
    <link name='fork'>
      <pose relative_to='base_to_fork'>0 0 0 0 -0 0</pose>
      <inertial>
        <pose>0 0 0 0 -0 0</pose>
        <mass>100</mass>
        <inertia>
          <ixx>0.2</ixx>
          <ixy>0</ixy>
          <ixz>0</ixz>
          <iyy>0.3</iyy>
          <iyz>0</iyz>
          <izz>0.4</izz>
        </inertia>
      </inertial>
      <collision name='fork_collision'>
        <pose>0 0 0 0 -0 0</pose>
        <geometry>
          <mesh>
            <scale>1 1 1</scale>
            <uri>model://forklift_robot_description/meshes/fork.dae</uri>
          </mesh>
        </geometry>
      </collision>
      <visual name='fork_visual'>
        <pose>0 0 0 0 -0 0</pose>
        <geometry>
          <mesh>
            <scale>1 1 1</scale>
            <uri>model://forklift_robot_description/meshes/fork.dae</uri>
          </mesh>
        </geometry>
      </visual>
    </link>
    <joint name='base_to_wheel_back_left' type='revolute'>
      <pose relative_to='base_footprint'>-0.7865 -0.5334 0.2032 0 -0 0</pose>
      <parent>base_footprint</parent>
      <child>wheel_back_left</child>
      <axis>
        <xyz>0 1 0</xyz>
        <limit>
          <lower>0</lower>
          <upper>0</upper>
          <effort>1000</effort>
          <velocity>10</velocity>
        </limit>
        <dynamics>
          <spring_reference>0</spring_reference>
          <spring_stiffness>0</spring_stiffness>
        </dynamics>
      </axis>
    </joint>
    <link name='wheel_back_left'>
      <pose relative_to='base_to_wheel_back_left'>0 0 0 0 -0 0</pose>
      <inertial>
        <pose>0 0 0 0 -0 0</pose>
        <mass>5</mass>
        <inertia>
          <ixx>0.001</ixx>
          <ixy>0</ixy>
          <ixz>0</ixz>
          <iyy>0.0015</iyy>
          <iyz>0</iyz>
          <izz>0.001</izz>
        </inertia>
      </inertial>
      <collision name='wheel_back_left_collision'>
        <pose>0 0.1 0 1.571 -0 0</pose>
        <geometry>
          <cylinder>
            <length>0.2</length>
            <radius>0.21</radius>
          </cylinder>
        </geometry>
      </collision>
      <visual name='wheel_back_left_visual'>
        <pose>-0.2032 0 -0.2032 0 -0 0</pose>
        <geometry>
          <mesh>
            <scale>1 1 1</scale>
            <uri>model://forklift_robot_description/meshes/wheel.dae</uri>
          </mesh>
        </geometry>
      </visual>
    </link>
    <joint name='base_to_wheel_back_right' type='revolute'>
      <pose relative_to='base_footprint'>-0.7502 0.3302 0.2032 0 -0 0</pose>
      <parent>base_footprint</parent>
      <child>wheel_back_right</child>
      <axis>
        <xyz>0 1 0</xyz>
        <limit>
          <lower>0</lower>
          <upper>0</upper>
          <effort>1000</effort>
          <velocity>10</velocity>
        </limit>
        <dynamics>
          <spring_reference>0</spring_reference>
          <spring_stiffness>0</spring_stiffness>
        </dynamics>
      </axis>
    </joint>
    <link name='wheel_back_right'>
      <pose relative_to='base_to_wheel_back_right'>0 0 0 0 -0 0</pose>
      <inertial>
        <pose>0 0 0 0 -0 0</pose>
        <mass>5</mass>
        <inertia>
          <ixx>0.001</ixx>
          <ixy>0</ixy>
          <ixz>0</ixz>
          <iyy>0.0015</iyy>
          <iyz>0</iyz>
          <izz>0.001</izz>
        </inertia>
      </inertial>
      <collision name='wheel_back_right_collision'>
        <pose>0 0.1 0 1.571 -0 0</pose>
        <geometry>
          <cylinder>
            <length>0.2</length>
            <radius>0.21</radius>
          </cylinder>
        </geometry>
      </collision>
      <visual name='wheel_back_right_visual'>
        <pose>-0.2032 0 -0.2032 0 -0 0</pose>
        <geometry>
          <mesh>
            <scale>1 1 1</scale>
            <uri>model://forklift_robot_description/meshes/wheel.dae</uri>
          </mesh>
        </geometry>
      </visual>
    </link>
    <joint name='base_to_wheel_front_left' type='revolute'>
      <pose relative_to='base_footprint'>0.6722 0.3302 0.2032 0 -0 0</pose>
      <parent>base_footprint</parent>
      <child>wheel_front_left</child>
      <axis>
        <xyz>0 1 0</xyz>
        <limit>
          <lower>0</lower>
          <upper>0</upper>
          <effort>1000</effort>
          <velocity>10</velocity>
        </limit>
        <dynamics>
          <spring_reference>0</spring_reference>
          <spring_stiffness>0</spring_stiffness>
        </dynamics>
      </axis>
    </joint>
    <link name='wheel_front_left'>
      <pose relative_to='base_to_wheel_front_left'>0 0 0 0 -0 0</pose>
      <inertial>
        <pose>0 0 0 0 -0 0</pose>
        <mass>5</mass>
        <inertia>
          <ixx>0.001</ixx>
          <ixy>0</ixy>
          <ixz>0</ixz>
          <iyy>0.0015</iyy>
          <iyz>0</iyz>
          <izz>0.001</izz>
        </inertia>
      </inertial>
      <collision name='wheel_front_left_collision'>
        <pose>0 0.1 0 1.571 -0 0</pose>
        <geometry>
          <cylinder>
            <length>0.2</length>
            <radius>0.21</radius>
          </cylinder>
        </geometry>
      </collision>
      <visual name='wheel_front_left_visual'>
        <pose>-0.2032 0 -0.2032 0 -0 0</pose>
        <geometry>
          <mesh>
            <scale>1 1 1</scale>
            <uri>model://forklift_robot_description/meshes/wheel.dae</uri>
          </mesh>
        </geometry>
      </visual>
    </link>
    <joint name='base_to_wheel_front_right' type='revolute'>
      <pose relative_to='base_footprint'>0.6722 -0.5334 0.2032 0 -0 0</pose>
      <parent>base_footprint</parent>
      <child>wheel_front_right</child>
      <axis>
        <xyz>0 1 0</xyz>
        <limit>
          <lower>0</lower>
          <upper>0</upper>
          <effort>1000</effort>
          <velocity>10</velocity>
        </limit>
        <dynamics>
          <spring_reference>0</spring_reference>
          <spring_stiffness>0</spring_stiffness>
        </dynamics>
      </axis>
    </joint>
    <link name='wheel_front_right'>
      <pose relative_to='base_to_wheel_front_right'>0 0 0 0 -0 0</pose>
      <inertial>
        <pose>0 0 0 0 -0 0</pose>
        <mass>5</mass>
        <inertia>
          <ixx>0.001</ixx>
          <ixy>0</ixy>
          <ixz>0</ixz>
          <iyy>0.0015</iyy>
          <iyz>0</iyz>
          <izz>0.001</izz>
        </inertia>
      </inertial>
      <collision name='wheel_front_right_collision'>
        <pose>0 0.1 0 1.571 -0 0</pose>
        <geometry>
          <cylinder>
            <length>0.2</length>
            <radius>0.21</radius>
          </cylinder>
        </geometry>
      </collision>
      <visual name='wheel_front_right_visual'>
        <pose>-0.2032 0 -0.2032 0 -0 0</pose>
        <geometry>
          <mesh>
            <scale>1 1 1</scale>
            <uri>model://forklift_robot_description/meshes/wheel.dae</uri>
          </mesh>
        </geometry>
      </visual>
    </link>
    <frame name='gps_joint' attached_to='base_link'>
      <pose>0.1 0 0.05 0 -0 0</pose>
    </frame>
    <frame name='gps_link' attached_to='gps_joint'/>
    <frame name='imu_joint' attached_to='base_link'>
      <pose>-0.1 0 0.05 0 -0 0</pose>
    </frame>
    <frame name='imu_link' attached_to='imu_joint'/>
    <frame name='lidar_joint' attached_to='base_link'>
      <pose>0.215 0 0.13 0 -0 0</pose>
    </frame>
    <frame name='lidar_link' attached_to='lidar_joint'/>
    <frame name='base_joint' attached_to='base_footprint'>
      <pose>0 0 0 0 -0 0</pose>
    </frame>
    <frame name='base_link' attached_to='base_joint'/>
  </model>
</sdf>
